[2024-03-19T15:46:06.327+0000] {taskinstance.py:1979} INFO - Dependencies all met for dep_context=non-requeueable deps ti=<TaskInstance: s3_to_postgres_dag.download_data_from_s3 manual__2024-03-19T15:46:05.099079+00:00 [queued]>
[2024-03-19T15:46:06.337+0000] {taskinstance.py:1979} INFO - Dependencies all met for dep_context=requeueable deps ti=<TaskInstance: s3_to_postgres_dag.download_data_from_s3 manual__2024-03-19T15:46:05.099079+00:00 [queued]>
[2024-03-19T15:46:06.338+0000] {taskinstance.py:2193} INFO - Starting attempt 1 of 2
[2024-03-19T15:46:06.344+0000] {taskinstance.py:2214} INFO - Executing <Task(PythonOperator): download_data_from_s3> on 2024-03-19 15:46:05.099079+00:00
[2024-03-19T15:46:06.348+0000] {standard_task_runner.py:60} INFO - Started process 453 to run task
[2024-03-19T15:46:06.350+0000] {standard_task_runner.py:87} INFO - Running: ['***', 'tasks', 'run', 's3_to_postgres_dag', 'download_data_from_s3', 'manual__2024-03-19T15:46:05.099079+00:00', '--job-id', '35', '--raw', '--subdir', 'DAGS_FOLDER/dag_prepare_s3_rds.py', '--cfg-path', '/tmp/tmp_85por6u']
[2024-03-19T15:46:06.353+0000] {standard_task_runner.py:88} INFO - Job 35: Subtask download_data_from_s3
[2024-03-19T15:46:06.380+0000] {task_command.py:423} INFO - Running <TaskInstance: s3_to_postgres_dag.download_data_from_s3 manual__2024-03-19T15:46:05.099079+00:00 [running]> on host 33271a7f5777
[2024-03-19T15:46:06.419+0000] {taskinstance.py:2510} INFO - Exporting env vars: AIRFLOW_CTX_DAG_OWNER='***' AIRFLOW_CTX_DAG_ID='s3_to_postgres_dag' AIRFLOW_CTX_TASK_ID='download_data_from_s3' AIRFLOW_CTX_EXECUTION_DATE='2024-03-19T15:46:05.099079+00:00' AIRFLOW_CTX_TRY_NUMBER='1' AIRFLOW_CTX_DAG_RUN_ID='manual__2024-03-19T15:46:05.099079+00:00'
[2024-03-19T15:46:06.421+0000] {taskinstance.py:2728} ERROR - Task failed with exception
Traceback (most recent call last):
  File "/home/airflow/.local/lib/python3.8/site-packages/airflow/models/taskinstance.py", line 444, in _execute_task
    result = _execute_callable(context=context, **execute_callable_kwargs)
  File "/home/airflow/.local/lib/python3.8/site-packages/airflow/models/taskinstance.py", line 414, in _execute_callable
    return execute_callable(context=context, **execute_callable_kwargs)
  File "/home/airflow/.local/lib/python3.8/site-packages/airflow/operators/python.py", line 200, in execute
    return_value = self.execute_callable()
  File "/home/airflow/.local/lib/python3.8/site-packages/airflow/operators/python.py", line 217, in execute_callable
    return self.python_callable(*self.op_args, **self.op_kwargs)
  File "/opt/airflow/dags/dag_prepare_s3_rds.py", line 60, in download_data_from_s3
    s3_hook = S3Hook(aws_conn_id=None,
  File "/home/airflow/.local/lib/python3.8/site-packages/airflow/providers/amazon/aws/hooks/s3.py", line 189, in __init__
    super().__init__(*args, **kwargs)
TypeError: __init__() got an unexpected keyword argument 'aws_access_key_id'
[2024-03-19T15:46:06.426+0000] {taskinstance.py:1149} INFO - Marking task as UP_FOR_RETRY. dag_id=s3_to_postgres_dag, task_id=download_data_from_s3, execution_date=20240319T154605, start_date=20240319T154606, end_date=20240319T154606
[2024-03-19T15:46:06.431+0000] {standard_task_runner.py:107} ERROR - Failed to execute job 35 for task download_data_from_s3 (__init__() got an unexpected keyword argument 'aws_access_key_id'; 453)
[2024-03-19T15:46:06.443+0000] {local_task_job_runner.py:234} INFO - Task exited with return code 1
[2024-03-19T15:46:06.455+0000] {taskinstance.py:3309} INFO - 0 downstream tasks scheduled from follow-on schedule check
