[2024-03-22T16:17:38.659+0000] {taskinstance.py:1979} INFO - Dependencies all met for dep_context=non-requeueable deps ti=<TaskInstance: aircraft_data_insertion.insert_data manual__2024-03-22T16:17:36.770726+00:00 [queued]>
[2024-03-22T16:17:38.664+0000] {taskinstance.py:1979} INFO - Dependencies all met for dep_context=requeueable deps ti=<TaskInstance: aircraft_data_insertion.insert_data manual__2024-03-22T16:17:36.770726+00:00 [queued]>
[2024-03-22T16:17:38.665+0000] {taskinstance.py:2193} INFO - Starting attempt 1 of 1
[2024-03-22T16:17:38.672+0000] {taskinstance.py:2214} INFO - Executing <Task(PythonOperator): insert_data> on 2024-03-22 16:17:36.770726+00:00
[2024-03-22T16:17:38.675+0000] {standard_task_runner.py:60} INFO - Started process 479 to run task
[2024-03-22T16:17:38.678+0000] {standard_task_runner.py:87} INFO - Running: ['***', 'tasks', 'run', 'aircraft_data_insertion', 'insert_data', 'manual__2024-03-22T16:17:36.770726+00:00', '--job-id', '91', '--raw', '--subdir', 'DAGS_FOLDER/dag_prep_3.py', '--cfg-path', '/tmp/tmph_4ksjlc']
[2024-03-22T16:17:38.679+0000] {standard_task_runner.py:88} INFO - Job 91: Subtask insert_data
[2024-03-22T16:17:38.708+0000] {task_command.py:423} INFO - Running <TaskInstance: aircraft_data_insertion.insert_data manual__2024-03-22T16:17:36.770726+00:00 [running]> on host 58dabeb1f433
[2024-03-22T16:17:38.747+0000] {taskinstance.py:2510} INFO - Exporting env vars: AIRFLOW_CTX_DAG_OWNER='***' AIRFLOW_CTX_DAG_ID='aircraft_data_insertion' AIRFLOW_CTX_TASK_ID='insert_data' AIRFLOW_CTX_EXECUTION_DATE='2024-03-22T16:17:36.770726+00:00' AIRFLOW_CTX_TRY_NUMBER='1' AIRFLOW_CTX_DAG_RUN_ID='manual__2024-03-22T16:17:36.770726+00:00'
[2024-03-22T16:17:38.755+0000] {taskinstance.py:2728} ERROR - Task failed with exception
Traceback (most recent call last):
  File "/home/airflow/.local/lib/python3.8/site-packages/airflow/models/taskinstance.py", line 444, in _execute_task
    result = _execute_callable(context=context, **execute_callable_kwargs)
  File "/home/airflow/.local/lib/python3.8/site-packages/airflow/models/taskinstance.py", line 414, in _execute_callable
    return execute_callable(context=context, **execute_callable_kwargs)
  File "/home/airflow/.local/lib/python3.8/site-packages/airflow/operators/python.py", line 200, in execute
    return_value = self.execute_callable()
  File "/home/airflow/.local/lib/python3.8/site-packages/airflow/operators/python.py", line 217, in execute_callable
    return self.python_callable(*self.op_args, **self.op_kwargs)
  File "/opt/airflow/dags/dag_prep_3.py", line 52, in insert_data
    with open('/opt/airflow/dags/data/aircraft_type/basic-ac-db.json') as f:
FileNotFoundError: [Errno 2] No such file or directory: '/opt/airflow/dags/data/aircraft_type/basic-ac-db.json'
[2024-03-22T16:17:38.760+0000] {taskinstance.py:1149} INFO - Marking task as FAILED. dag_id=aircraft_data_insertion, task_id=insert_data, execution_date=20240322T161736, start_date=20240322T161738, end_date=20240322T161738
[2024-03-22T16:17:38.766+0000] {standard_task_runner.py:107} ERROR - Failed to execute job 91 for task insert_data ([Errno 2] No such file or directory: '/opt/airflow/dags/data/aircraft_type/basic-ac-db.json'; 479)
[2024-03-22T16:17:38.812+0000] {local_task_job_runner.py:234} INFO - Task exited with return code 1
[2024-03-22T16:17:38.823+0000] {taskinstance.py:3309} INFO - 0 downstream tasks scheduled from follow-on schedule check
