[2024-03-22T15:33:36.296+0000] {taskinstance.py:1979} INFO - Dependencies all met for dep_context=non-requeueable deps ti=<TaskInstance: aircraft_data_processing.download_and_prepare_data manual__2024-03-22T15:33:35.185438+00:00 [queued]>
[2024-03-22T15:33:36.300+0000] {taskinstance.py:1979} INFO - Dependencies all met for dep_context=requeueable deps ti=<TaskInstance: aircraft_data_processing.download_and_prepare_data manual__2024-03-22T15:33:35.185438+00:00 [queued]>
[2024-03-22T15:33:36.300+0000] {taskinstance.py:2193} INFO - Starting attempt 1 of 2
[2024-03-22T15:33:36.307+0000] {taskinstance.py:2214} INFO - Executing <Task(PythonOperator): download_and_prepare_data> on 2024-03-22 15:33:35.185438+00:00
[2024-03-22T15:33:36.314+0000] {standard_task_runner.py:60} INFO - Started process 607 to run task
[2024-03-22T15:33:36.316+0000] {standard_task_runner.py:87} INFO - Running: ['***', 'tasks', 'run', 'aircraft_data_processing', 'download_and_prepare_data', 'manual__2024-03-22T15:33:35.185438+00:00', '--job-id', '70', '--raw', '--subdir', 'DAGS_FOLDER/dag_prep_2.py', '--cfg-path', '/tmp/tmpzimtx1js']
[2024-03-22T15:33:36.318+0000] {standard_task_runner.py:88} INFO - Job 70: Subtask download_and_prepare_data
[2024-03-22T15:33:36.351+0000] {task_command.py:423} INFO - Running <TaskInstance: aircraft_data_processing.download_and_prepare_data manual__2024-03-22T15:33:35.185438+00:00 [running]> on host c6b73a83fed6
[2024-03-22T15:33:36.405+0000] {taskinstance.py:2510} INFO - Exporting env vars: AIRFLOW_CTX_DAG_OWNER='***' AIRFLOW_CTX_DAG_ID='aircraft_data_processing' AIRFLOW_CTX_TASK_ID='download_and_prepare_data' AIRFLOW_CTX_EXECUTION_DATE='2024-03-22T15:33:35.185438+00:00' AIRFLOW_CTX_TRY_NUMBER='1' AIRFLOW_CTX_DAG_RUN_ID='manual__2024-03-22T15:33:35.185438+00:00'
[2024-03-22T15:33:36.533+0000] {dag_prep_2.py:91} INFO - Starting data download...
[2024-03-22T15:34:11.926+0000] {local_task_job_runner.py:302} WARNING - State of this instance has been externally set to None. Terminating instance.
[2024-03-22T15:34:11.936+0000] {process_utils.py:131} INFO - Sending 15 to group 607. PIDs of all processes in the group: [607]
[2024-03-22T15:34:11.936+0000] {process_utils.py:86} INFO - Sending the signal 15 to group 607
[2024-03-22T15:34:12.154+0000] {taskinstance.py:2480} ERROR - Received SIGTERM. Terminating subprocesses.
[2024-03-22T15:34:12.162+0000] {taskinstance.py:2728} ERROR - Task failed with exception
Traceback (most recent call last):
  File "/home/airflow/.local/lib/python3.8/site-packages/airflow/models/taskinstance.py", line 444, in _execute_task
    result = _execute_callable(context=context, **execute_callable_kwargs)
  File "/home/airflow/.local/lib/python3.8/site-packages/airflow/models/taskinstance.py", line 414, in _execute_callable
    return execute_callable(context=context, **execute_callable_kwargs)
  File "/home/airflow/.local/lib/python3.8/site-packages/airflow/operators/python.py", line 200, in execute
    return_value = self.execute_callable()
  File "/home/airflow/.local/lib/python3.8/site-packages/airflow/operators/python.py", line 217, in execute_callable
    return self.python_callable(*self.op_args, **self.op_kwargs)
  File "/opt/airflow/dags/dag_prep_2.py", line 157, in task_download_and_prepare_data
    formatted_data = download_and_prepare_data()
  File "/opt/airflow/dags/dag_prep_2.py", line 103, in download_and_prepare_data
    formatted_data = [format_for_db(ac) for ac in data_dict.get('aircraft', [])]
  File "/opt/airflow/dags/dag_prep_2.py", line 103, in <listcomp>
    formatted_data = [format_for_db(ac) for ac in data_dict.get('aircraft', [])]
  File "/opt/airflow/dags/dag_prep_2.py", line 56, in format_for_db
    for aircraft in data.get("aircraft", []):
  File "/home/airflow/.local/lib/python3.8/site-packages/airflow/models/taskinstance.py", line 2482, in signal_handler
    raise AirflowException("Task received SIGTERM signal")
airflow.exceptions.AirflowException: Task received SIGTERM signal
[2024-03-22T15:34:12.165+0000] {taskinstance.py:1149} INFO - Marking task as FAILED. dag_id=aircraft_data_processing, task_id=download_and_prepare_data, execution_date=20240322T153335, start_date=20240322T153336, end_date=20240322T153412
[2024-03-22T15:34:12.174+0000] {standard_task_runner.py:107} ERROR - Failed to execute job 70 for task download_and_prepare_data ((psycopg2.errors.ForeignKeyViolation) insert or update on table "task_fail" violates foreign key constraint "task_fail_ti_fkey"
DETAIL:  Key (dag_id, task_id, run_id, map_index)=(aircraft_data_processing, download_and_prepare_data, manual__2024-03-22T15:33:35.185438+00:00, -1) is not present in table "task_instance".

[SQL: INSERT INTO task_fail (task_id, dag_id, run_id, map_index, start_date, end_date, duration) VALUES (%(task_id)s, %(dag_id)s, %(run_id)s, %(map_index)s, %(start_date)s, %(end_date)s, %(duration)s) RETURNING task_fail.id]
[parameters: {'task_id': 'download_and_prepare_data', 'dag_id': 'aircraft_data_processing', 'run_id': 'manual__2024-03-22T15:33:35.185438+00:00', 'map_index': -1, 'start_date': datetime.datetime(2024, 3, 22, 15, 33, 36, 296701, tzinfo=Timezone('UTC')), 'end_date': datetime.datetime(2024, 3, 22, 15, 34, 12, 165262, tzinfo=Timezone('UTC')), 'duration': 35}]
(Background on this error at: https://sqlalche.me/e/14/gkpj); 607)
[2024-03-22T15:34:12.237+0000] {process_utils.py:79} INFO - Process psutil.Process(pid=607, status='terminated', exitcode=1, started='15:33:35') (607) terminated with exit code 1
