[2024-03-20T15:16:59.122+0000] {taskinstance.py:1979} INFO - Dependencies all met for dep_context=non-requeueable deps ti=<TaskInstance: aircraft_data_insertion.insert_data manual__2024-03-20T15:16:57.393083+00:00 [queued]>
[2024-03-20T15:16:59.126+0000] {taskinstance.py:1979} INFO - Dependencies all met for dep_context=requeueable deps ti=<TaskInstance: aircraft_data_insertion.insert_data manual__2024-03-20T15:16:57.393083+00:00 [queued]>
[2024-03-20T15:16:59.126+0000] {taskinstance.py:2193} INFO - Starting attempt 1 of 1
[2024-03-20T15:16:59.131+0000] {taskinstance.py:2214} INFO - Executing <Task(PythonOperator): insert_data> on 2024-03-20 15:16:57.393083+00:00
[2024-03-20T15:16:59.134+0000] {standard_task_runner.py:60} INFO - Started process 11517 to run task
[2024-03-20T15:16:59.136+0000] {standard_task_runner.py:87} INFO - Running: ['***', 'tasks', 'run', 'aircraft_data_insertion', 'insert_data', 'manual__2024-03-20T15:16:57.393083+00:00', '--job-id', '53', '--raw', '--subdir', 'DAGS_FOLDER/dag_prep_3.py', '--cfg-path', '/tmp/tmp7ietjf8a']
[2024-03-20T15:16:59.137+0000] {standard_task_runner.py:88} INFO - Job 53: Subtask insert_data
[2024-03-20T15:16:59.160+0000] {task_command.py:423} INFO - Running <TaskInstance: aircraft_data_insertion.insert_data manual__2024-03-20T15:16:57.393083+00:00 [running]> on host 33271a7f5777
[2024-03-20T15:16:59.191+0000] {taskinstance.py:2510} INFO - Exporting env vars: AIRFLOW_CTX_DAG_OWNER='***' AIRFLOW_CTX_DAG_ID='aircraft_data_insertion' AIRFLOW_CTX_TASK_ID='insert_data' AIRFLOW_CTX_EXECUTION_DATE='2024-03-20T15:16:57.393083+00:00' AIRFLOW_CTX_TRY_NUMBER='1' AIRFLOW_CTX_DAG_RUN_ID='manual__2024-03-20T15:16:57.393083+00:00'
[2024-03-20T15:16:59.217+0000] {taskinstance.py:2728} ERROR - Task failed with exception
Traceback (most recent call last):
  File "/home/airflow/.local/lib/python3.8/site-packages/airflow/models/taskinstance.py", line 444, in _execute_task
    result = _execute_callable(context=context, **execute_callable_kwargs)
  File "/home/airflow/.local/lib/python3.8/site-packages/airflow/models/taskinstance.py", line 414, in _execute_callable
    return execute_callable(context=context, **execute_callable_kwargs)
  File "/home/airflow/.local/lib/python3.8/site-packages/airflow/operators/python.py", line 200, in execute
    return_value = self.execute_callable()
  File "/home/airflow/.local/lib/python3.8/site-packages/airflow/operators/python.py", line 217, in execute_callable
    return self.python_callable(*self.op_args, **self.op_kwargs)
  File "/opt/airflow/dags/dag_prep_3.py", line 51, in insert_data
    with open(f'{directory_path}/basic-ac-db.json') as f:
FileNotFoundError: [Errno 2] No such file or directory: '/Users/vanessabragacosta/Documents/S8_Clone/big-data-infrastructure-exercises/airflow/dags/data/aircraft_type/basic-ac-db.json'
[2024-03-20T15:16:59.222+0000] {taskinstance.py:1149} INFO - Marking task as FAILED. dag_id=aircraft_data_insertion, task_id=insert_data, execution_date=20240320T151657, start_date=20240320T151659, end_date=20240320T151659
[2024-03-20T15:16:59.227+0000] {standard_task_runner.py:107} ERROR - Failed to execute job 53 for task insert_data ([Errno 2] No such file or directory: '/Users/vanessabragacosta/Documents/S8_Clone/big-data-infrastructure-exercises/airflow/dags/data/aircraft_type/basic-ac-db.json'; 11517)
[2024-03-20T15:16:59.268+0000] {local_task_job_runner.py:234} INFO - Task exited with return code 1
[2024-03-20T15:16:59.286+0000] {taskinstance.py:3309} INFO - 0 downstream tasks scheduled from follow-on schedule check
