[2024-03-19T15:41:59.117+0000] {taskinstance.py:1979} INFO - Dependencies all met for dep_context=non-requeueable deps ti=<TaskInstance: s3_to_postgres_dag.download_data_from_s3 manual__2024-03-19T15:41:57.274421+00:00 [queued]>
[2024-03-19T15:41:59.121+0000] {taskinstance.py:1979} INFO - Dependencies all met for dep_context=requeueable deps ti=<TaskInstance: s3_to_postgres_dag.download_data_from_s3 manual__2024-03-19T15:41:57.274421+00:00 [queued]>
[2024-03-19T15:41:59.121+0000] {taskinstance.py:2193} INFO - Starting attempt 1 of 2
[2024-03-19T15:41:59.127+0000] {taskinstance.py:2214} INFO - Executing <Task(PythonOperator): download_data_from_s3> on 2024-03-19 15:41:57.274421+00:00
[2024-03-19T15:41:59.132+0000] {standard_task_runner.py:60} INFO - Started process 383 to run task
[2024-03-19T15:41:59.134+0000] {standard_task_runner.py:87} INFO - Running: ['***', 'tasks', 'run', 's3_to_postgres_dag', 'download_data_from_s3', 'manual__2024-03-19T15:41:57.274421+00:00', '--job-id', '33', '--raw', '--subdir', 'DAGS_FOLDER/dag_prepare_s3_rds.py', '--cfg-path', '/tmp/tmpdqf0z92i']
[2024-03-19T15:41:59.136+0000] {standard_task_runner.py:88} INFO - Job 33: Subtask download_data_from_s3
[2024-03-19T15:41:59.165+0000] {task_command.py:423} INFO - Running <TaskInstance: s3_to_postgres_dag.download_data_from_s3 manual__2024-03-19T15:41:57.274421+00:00 [running]> on host 33271a7f5777
[2024-03-19T15:41:59.214+0000] {taskinstance.py:2510} INFO - Exporting env vars: AIRFLOW_CTX_DAG_OWNER='***' AIRFLOW_CTX_DAG_ID='s3_to_postgres_dag' AIRFLOW_CTX_TASK_ID='download_data_from_s3' AIRFLOW_CTX_EXECUTION_DATE='2024-03-19T15:41:57.274421+00:00' AIRFLOW_CTX_TRY_NUMBER='1' AIRFLOW_CTX_DAG_RUN_ID='manual__2024-03-19T15:41:57.274421+00:00'
[2024-03-19T15:41:59.217+0000] {base_aws.py:161} INFO - No connection ID provided. Fallback on boto3 credential strategy (region_name=None). See: https://boto3.amazonaws.com/v1/documentation/api/latest/guide/configuration.html
[2024-03-19T15:42:01.535+0000] {taskinstance.py:2728} ERROR - Task failed with exception
Traceback (most recent call last):
  File "/home/airflow/.local/lib/python3.8/site-packages/airflow/models/taskinstance.py", line 444, in _execute_task
    result = _execute_callable(context=context, **execute_callable_kwargs)
  File "/home/airflow/.local/lib/python3.8/site-packages/airflow/models/taskinstance.py", line 414, in _execute_callable
    return execute_callable(context=context, **execute_callable_kwargs)
  File "/home/airflow/.local/lib/python3.8/site-packages/airflow/operators/python.py", line 200, in execute
    return_value = self.execute_callable()
  File "/home/airflow/.local/lib/python3.8/site-packages/airflow/operators/python.py", line 217, in execute_callable
    return self.python_callable(*self.op_args, **self.op_kwargs)
  File "/opt/airflow/dags/dag_prepare_s3_rds.py", line 61, in download_data_from_s3
    keys = s3_hook.list_keys(bucket_name=bucket_name, prefix=prefix)
  File "/home/airflow/.local/lib/python3.8/site-packages/airflow/providers/amazon/aws/hooks/s3.py", line 91, in wrapper
    return func(*bound_args.args, **bound_args.kwargs)
  File "/home/airflow/.local/lib/python3.8/site-packages/airflow/providers/amazon/aws/hooks/s3.py", line 842, in list_keys
    for page in response:
  File "/home/airflow/.local/lib/python3.8/site-packages/botocore/paginate.py", line 269, in __iter__
    response = self._make_request(current_kwargs)
  File "/home/airflow/.local/lib/python3.8/site-packages/botocore/paginate.py", line 357, in _make_request
    return self._method(**current_kwargs)
  File "/home/airflow/.local/lib/python3.8/site-packages/botocore/client.py", line 553, in _api_call
    return self._make_api_call(operation_name, kwargs)
  File "/home/airflow/.local/lib/python3.8/site-packages/botocore/client.py", line 989, in _make_api_call
    http, parsed_response = self._make_request(
  File "/home/airflow/.local/lib/python3.8/site-packages/botocore/client.py", line 1015, in _make_request
    return self._endpoint.make_request(operation_model, request_dict)
  File "/home/airflow/.local/lib/python3.8/site-packages/botocore/endpoint.py", line 119, in make_request
    return self._send_request(request_dict, operation_model)
  File "/home/airflow/.local/lib/python3.8/site-packages/botocore/endpoint.py", line 198, in _send_request
    request = self.create_request(request_dict, operation_model)
  File "/home/airflow/.local/lib/python3.8/site-packages/botocore/endpoint.py", line 134, in create_request
    self._event_emitter.emit(
  File "/home/airflow/.local/lib/python3.8/site-packages/botocore/hooks.py", line 412, in emit
    return self._emitter.emit(aliased_event_name, **kwargs)
  File "/home/airflow/.local/lib/python3.8/site-packages/botocore/hooks.py", line 256, in emit
    return self._emit(event_name, kwargs)
  File "/home/airflow/.local/lib/python3.8/site-packages/botocore/hooks.py", line 239, in _emit
    response = handler(**kwargs)
  File "/home/airflow/.local/lib/python3.8/site-packages/botocore/signers.py", line 105, in handler
    return self.sign(operation_name, request)
  File "/home/airflow/.local/lib/python3.8/site-packages/botocore/signers.py", line 195, in sign
    auth.add_auth(request)
  File "/home/airflow/.local/lib/python3.8/site-packages/botocore/auth.py", line 418, in add_auth
    raise NoCredentialsError()
botocore.exceptions.NoCredentialsError: Unable to locate credentials
[2024-03-19T15:42:01.543+0000] {taskinstance.py:1149} INFO - Marking task as UP_FOR_RETRY. dag_id=s3_to_postgres_dag, task_id=download_data_from_s3, execution_date=20240319T154157, start_date=20240319T154159, end_date=20240319T154201
[2024-03-19T15:42:01.551+0000] {standard_task_runner.py:107} ERROR - Failed to execute job 33 for task download_data_from_s3 (Unable to locate credentials; 383)
[2024-03-19T15:42:01.597+0000] {local_task_job_runner.py:234} INFO - Task exited with return code 1
[2024-03-19T15:42:01.626+0000] {taskinstance.py:3309} INFO - 0 downstream tasks scheduled from follow-on schedule check
