[2024-03-19T20:43:28.338+0000] {taskinstance.py:1979} INFO - Dependencies all met for dep_context=non-requeueable deps ti=<TaskInstance: s3_to_postgres_dag.download_data_from_s3 manual__2024-03-19T20:43:27.129073+00:00 [queued]>
[2024-03-19T20:43:28.343+0000] {taskinstance.py:1979} INFO - Dependencies all met for dep_context=requeueable deps ti=<TaskInstance: s3_to_postgres_dag.download_data_from_s3 manual__2024-03-19T20:43:27.129073+00:00 [queued]>
[2024-03-19T20:43:28.343+0000] {taskinstance.py:2193} INFO - Starting attempt 1 of 2
[2024-03-19T20:43:28.350+0000] {taskinstance.py:2214} INFO - Executing <Task(PythonOperator): download_data_from_s3> on 2024-03-19 20:43:27.129073+00:00
[2024-03-19T20:43:28.355+0000] {standard_task_runner.py:60} INFO - Started process 3432 to run task
[2024-03-19T20:43:28.358+0000] {standard_task_runner.py:87} INFO - Running: ['***', 'tasks', 'run', 's3_to_postgres_dag', 'download_data_from_s3', 'manual__2024-03-19T20:43:27.129073+00:00', '--job-id', '42', '--raw', '--subdir', 'DAGS_FOLDER/dag_prepare_s3_rds.py', '--cfg-path', '/tmp/tmpkkz2cv9h']
[2024-03-19T20:43:28.362+0000] {standard_task_runner.py:88} INFO - Job 42: Subtask download_data_from_s3
[2024-03-19T20:43:28.410+0000] {task_command.py:423} INFO - Running <TaskInstance: s3_to_postgres_dag.download_data_from_s3 manual__2024-03-19T20:43:27.129073+00:00 [running]> on host 33271a7f5777
[2024-03-19T20:43:28.480+0000] {taskinstance.py:2510} INFO - Exporting env vars: AIRFLOW_CTX_DAG_OWNER='***' AIRFLOW_CTX_DAG_ID='s3_to_postgres_dag' AIRFLOW_CTX_TASK_ID='download_data_from_s3' AIRFLOW_CTX_EXECUTION_DATE='2024-03-19T20:43:27.129073+00:00' AIRFLOW_CTX_TRY_NUMBER='1' AIRFLOW_CTX_DAG_RUN_ID='manual__2024-03-19T20:43:27.129073+00:00'
[2024-03-19T20:43:28.684+0000] {taskinstance.py:2728} ERROR - Task failed with exception
Traceback (most recent call last):
  File "/home/airflow/.local/lib/python3.8/site-packages/airflow/models/taskinstance.py", line 444, in _execute_task
    result = _execute_callable(context=context, **execute_callable_kwargs)
  File "/home/airflow/.local/lib/python3.8/site-packages/airflow/models/taskinstance.py", line 414, in _execute_callable
    return execute_callable(context=context, **execute_callable_kwargs)
  File "/home/airflow/.local/lib/python3.8/site-packages/airflow/operators/python.py", line 200, in execute
    return_value = self.execute_callable()
  File "/home/airflow/.local/lib/python3.8/site-packages/airflow/operators/python.py", line 217, in execute_callable
    return self.python_callable(*self.op_args, **self.op_kwargs)
  File "/opt/airflow/dags/dag_prepare_s3_rds.py", line 69, in download_data_from_s3
    keys = s3_hook.list_keys(bucket_name=bucket_name, prefix=prefix)
  File "/home/airflow/.local/lib/python3.8/site-packages/airflow/providers/amazon/aws/hooks/s3.py", line 91, in wrapper
    return func(*bound_args.args, **bound_args.kwargs)
  File "/home/airflow/.local/lib/python3.8/site-packages/airflow/providers/amazon/aws/hooks/s3.py", line 832, in list_keys
    paginator = self.get_conn().get_paginator("list_objects_v2")
AttributeError: 's3.ServiceResource' object has no attribute 'get_paginator'
[2024-03-19T20:43:28.694+0000] {taskinstance.py:1149} INFO - Marking task as UP_FOR_RETRY. dag_id=s3_to_postgres_dag, task_id=download_data_from_s3, execution_date=20240319T204327, start_date=20240319T204328, end_date=20240319T204328
[2024-03-19T20:43:28.703+0000] {standard_task_runner.py:107} ERROR - Failed to execute job 42 for task download_data_from_s3 ('s3.ServiceResource' object has no attribute 'get_paginator'; 3432)
[2024-03-19T20:43:28.735+0000] {local_task_job_runner.py:234} INFO - Task exited with return code 1
[2024-03-19T20:43:28.751+0000] {taskinstance.py:3309} INFO - 0 downstream tasks scheduled from follow-on schedule check
