[2024-03-20T14:49:21.423+0000] {taskinstance.py:1979} INFO - Dependencies all met for dep_context=non-requeueable deps ti=<TaskInstance: aircraft_data_insertion.create_tables manual__2024-03-20T14:49:20.469440+00:00 [queued]>
[2024-03-20T14:49:21.429+0000] {taskinstance.py:1979} INFO - Dependencies all met for dep_context=requeueable deps ti=<TaskInstance: aircraft_data_insertion.create_tables manual__2024-03-20T14:49:20.469440+00:00 [queued]>
[2024-03-20T14:49:21.429+0000] {taskinstance.py:2193} INFO - Starting attempt 1 of 1
[2024-03-20T14:49:21.436+0000] {taskinstance.py:2214} INFO - Executing <Task(PythonOperator): create_tables> on 2024-03-20 14:49:20.469440+00:00
[2024-03-20T14:49:21.440+0000] {standard_task_runner.py:60} INFO - Started process 11090 to run task
[2024-03-20T14:49:21.460+0000] {standard_task_runner.py:87} INFO - Running: ['***', 'tasks', 'run', 'aircraft_data_insertion', 'create_tables', 'manual__2024-03-20T14:49:20.469440+00:00', '--job-id', '47', '--raw', '--subdir', 'DAGS_FOLDER/dag_prep_3.py', '--cfg-path', '/tmp/tmpw72h0s4j']
[2024-03-20T14:49:21.462+0000] {standard_task_runner.py:88} INFO - Job 47: Subtask create_tables
[2024-03-20T14:49:21.524+0000] {task_command.py:423} INFO - Running <TaskInstance: aircraft_data_insertion.create_tables manual__2024-03-20T14:49:20.469440+00:00 [running]> on host 33271a7f5777
[2024-03-20T14:49:21.567+0000] {taskinstance.py:2510} INFO - Exporting env vars: AIRFLOW_CTX_DAG_OWNER='***' AIRFLOW_CTX_DAG_ID='aircraft_data_insertion' AIRFLOW_CTX_TASK_ID='create_tables' AIRFLOW_CTX_EXECUTION_DATE='2024-03-20T14:49:20.469440+00:00' AIRFLOW_CTX_TRY_NUMBER='1' AIRFLOW_CTX_DAG_RUN_ID='manual__2024-03-20T14:49:20.469440+00:00'
[2024-03-20T14:49:21.569+0000] {taskinstance.py:2728} ERROR - Task failed with exception
Traceback (most recent call last):
  File "/home/airflow/.local/lib/python3.8/site-packages/airflow/models/taskinstance.py", line 444, in _execute_task
    result = _execute_callable(context=context, **execute_callable_kwargs)
  File "/home/airflow/.local/lib/python3.8/site-packages/airflow/models/taskinstance.py", line 414, in _execute_callable
    return execute_callable(context=context, **execute_callable_kwargs)
  File "/home/airflow/.local/lib/python3.8/site-packages/airflow/operators/python.py", line 200, in execute
    return_value = self.execute_callable()
  File "/home/airflow/.local/lib/python3.8/site-packages/airflow/operators/python.py", line 217, in execute_callable
    return self.python_callable(*self.op_args, **self.op_kwargs)
  File "/opt/airflow/dags/dag_prep_3.py", line 17, in create_tables
    conn = psycopg2.connect(
  File "/home/airflow/.local/lib/python3.8/site-packages/psycopg2/__init__.py", line 122, in connect
    conn = _connect(dsn, connection_factory=connection_factory, **kwasync)
psycopg2.OperationalError: connection to server at "localhost" (127.0.0.1), port 5433 failed: Connection refused
	Is the server running on that host and accepting TCP/IP connections?
connection to server at "localhost" (::1), port 5433 failed: Cannot assign requested address
	Is the server running on that host and accepting TCP/IP connections?

[2024-03-20T14:49:21.583+0000] {taskinstance.py:1149} INFO - Marking task as FAILED. dag_id=aircraft_data_insertion, task_id=create_tables, execution_date=20240320T144920, start_date=20240320T144921, end_date=20240320T144921
[2024-03-20T14:49:21.590+0000] {standard_task_runner.py:107} ERROR - Failed to execute job 47 for task create_tables (connection to server at "localhost" (127.0.0.1), port 5433 failed: Connection refused
	Is the server running on that host and accepting TCP/IP connections?
connection to server at "localhost" (::1), port 5433 failed: Cannot assign requested address
	Is the server running on that host and accepting TCP/IP connections?
; 11090)
[2024-03-20T14:49:21.633+0000] {local_task_job_runner.py:234} INFO - Task exited with return code 1
[2024-03-20T14:49:21.648+0000] {taskinstance.py:3309} INFO - 0 downstream tasks scheduled from follow-on schedule check
