[2024-03-22T15:32:21.060+0000] {taskinstance.py:1979} INFO - Dependencies all met for dep_context=non-requeueable deps ti=<TaskInstance: aircraft_data_processing.download_and_prepare_data manual__2024-03-22T15:32:19.078534+00:00 [queued]>
[2024-03-22T15:32:21.069+0000] {taskinstance.py:1979} INFO - Dependencies all met for dep_context=requeueable deps ti=<TaskInstance: aircraft_data_processing.download_and_prepare_data manual__2024-03-22T15:32:19.078534+00:00 [queued]>
[2024-03-22T15:32:21.070+0000] {taskinstance.py:2193} INFO - Starting attempt 1 of 2
[2024-03-22T15:32:21.077+0000] {taskinstance.py:2214} INFO - Executing <Task(PythonOperator): download_and_prepare_data> on 2024-03-22 15:32:19.078534+00:00
[2024-03-22T15:32:21.091+0000] {standard_task_runner.py:60} INFO - Started process 588 to run task
[2024-03-22T15:32:21.100+0000] {standard_task_runner.py:87} INFO - Running: ['***', 'tasks', 'run', 'aircraft_data_processing', 'download_and_prepare_data', 'manual__2024-03-22T15:32:19.078534+00:00', '--job-id', '69', '--raw', '--subdir', 'DAGS_FOLDER/dag_prep_2.py', '--cfg-path', '/tmp/tmp1wrlxuq9']
[2024-03-22T15:32:21.104+0000] {standard_task_runner.py:88} INFO - Job 69: Subtask download_and_prepare_data
[2024-03-22T15:32:21.135+0000] {task_command.py:423} INFO - Running <TaskInstance: aircraft_data_processing.download_and_prepare_data manual__2024-03-22T15:32:19.078534+00:00 [running]> on host c6b73a83fed6
[2024-03-22T15:32:21.176+0000] {taskinstance.py:2510} INFO - Exporting env vars: AIRFLOW_CTX_DAG_OWNER='***' AIRFLOW_CTX_DAG_ID='aircraft_data_processing' AIRFLOW_CTX_TASK_ID='download_and_prepare_data' AIRFLOW_CTX_EXECUTION_DATE='2024-03-22T15:32:19.078534+00:00' AIRFLOW_CTX_TRY_NUMBER='1' AIRFLOW_CTX_DAG_RUN_ID='manual__2024-03-22T15:32:19.078534+00:00'
[2024-03-22T15:32:21.270+0000] {dag_prep_2.py:91} INFO - Starting data download...
[2024-03-22T15:32:22.819+0000] {taskinstance.py:2728} ERROR - Task failed with exception
Traceback (most recent call last):
  File "/home/airflow/.local/lib/python3.8/site-packages/airflow/models/taskinstance.py", line 444, in _execute_task
    result = _execute_callable(context=context, **execute_callable_kwargs)
  File "/home/airflow/.local/lib/python3.8/site-packages/airflow/models/taskinstance.py", line 414, in _execute_callable
    return execute_callable(context=context, **execute_callable_kwargs)
  File "/home/airflow/.local/lib/python3.8/site-packages/airflow/operators/python.py", line 200, in execute
    return_value = self.execute_callable()
  File "/home/airflow/.local/lib/python3.8/site-packages/airflow/operators/python.py", line 217, in execute_callable
    return self.python_callable(*self.op_args, **self.op_kwargs)
  File "/opt/airflow/dags/dag_prep_2.py", line 157, in task_download_and_prepare_data
    formatted_data = download_and_prepare_data()
  File "/opt/airflow/dags/dag_prep_2.py", line 103, in download_and_prepare_data
    formatted_data = [format_for_db(ac) for ac in data_dict.get('aircraft', [])]
  File "/opt/airflow/dags/dag_prep_2.py", line 103, in <listcomp>
    formatted_data = [format_for_db(ac) for ac in data_dict.get('aircraft', [])]
NameError: name 'format_for_db' is not defined
[2024-03-22T15:32:22.862+0000] {taskinstance.py:1149} INFO - Marking task as UP_FOR_RETRY. dag_id=aircraft_data_processing, task_id=download_and_prepare_data, execution_date=20240322T153219, start_date=20240322T153221, end_date=20240322T153222
[2024-03-22T15:32:22.877+0000] {standard_task_runner.py:107} ERROR - Failed to execute job 69 for task download_and_prepare_data (name 'format_for_db' is not defined; 588)
[2024-03-22T15:32:22.899+0000] {local_task_job_runner.py:234} INFO - Task exited with return code 1
[2024-03-22T15:32:22.943+0000] {taskinstance.py:3309} INFO - 0 downstream tasks scheduled from follow-on schedule check
