[2024-03-13T19:53:20.082+0000] {taskinstance.py:1979} INFO - Dependencies all met for dep_context=non-requeueable deps ti=<TaskInstance: download_readsb_hist.check_if_data_exists manual__2024-03-13T19:07:52.601012+00:00 [queued]>
[2024-03-13T19:53:20.088+0000] {taskinstance.py:1979} INFO - Dependencies all met for dep_context=requeueable deps ti=<TaskInstance: download_readsb_hist.check_if_data_exists manual__2024-03-13T19:07:52.601012+00:00 [queued]>
[2024-03-13T19:53:20.088+0000] {taskinstance.py:2193} INFO - Starting attempt 2 of 2
[2024-03-13T19:53:20.096+0000] {taskinstance.py:2214} INFO - Executing <Task(PythonOperator): check_if_data_exists> on 2024-03-13 19:07:52.601012+00:00
[2024-03-13T19:53:20.101+0000] {standard_task_runner.py:60} INFO - Started process 552 to run task
[2024-03-13T19:53:20.107+0000] {standard_task_runner.py:87} INFO - Running: ['***', 'tasks', 'run', 'download_readsb_hist', 'check_if_data_exists', 'manual__2024-03-13T19:07:52.601012+00:00', '--job-id', '17', '--raw', '--subdir', 'DAGS_FOLDER/dag_download.py', '--cfg-path', '/tmp/tmpm1q4xcw0']
[2024-03-13T19:53:20.110+0000] {standard_task_runner.py:88} INFO - Job 17: Subtask check_if_data_exists
[2024-03-13T19:53:20.177+0000] {task_command.py:423} INFO - Running <TaskInstance: download_readsb_hist.check_if_data_exists manual__2024-03-13T19:07:52.601012+00:00 [running]> on host 33271a7f5777
[2024-03-13T19:53:20.261+0000] {taskinstance.py:2510} INFO - Exporting env vars: AIRFLOW_CTX_DAG_OWNER='***' AIRFLOW_CTX_DAG_ID='download_readsb_hist' AIRFLOW_CTX_TASK_ID='check_if_data_exists' AIRFLOW_CTX_EXECUTION_DATE='2024-03-13T19:07:52.601012+00:00' AIRFLOW_CTX_TRY_NUMBER='2' AIRFLOW_CTX_DAG_RUN_ID='manual__2024-03-13T19:07:52.601012+00:00'
[2024-03-13T19:53:20.263+0000] {logging_mixin.py:188} INFO - Checking if data already exists in S3...
[2024-03-13T19:53:22.278+0000] {taskinstance.py:2728} ERROR - Task failed with exception
Traceback (most recent call last):
  File "/home/airflow/.local/lib/python3.8/site-packages/urllib3/connection.py", line 174, in _new_conn
    conn = connection.create_connection(
  File "/home/airflow/.local/lib/python3.8/site-packages/urllib3/util/connection.py", line 72, in create_connection
    for res in socket.getaddrinfo(host, port, family, socket.SOCK_STREAM):
  File "/usr/local/lib/python3.8/socket.py", line 918, in getaddrinfo
    for res in _socket.getaddrinfo(host, port, family, type, proto, flags):
socket.gaierror: [Errno -2] Name or service not known

During handling of the above exception, another exception occurred:

Traceback (most recent call last):
  File "/home/airflow/.local/lib/python3.8/site-packages/botocore/httpsession.py", line 464, in send
    urllib_response = conn.urlopen(
  File "/home/airflow/.local/lib/python3.8/site-packages/urllib3/connectionpool.py", line 799, in urlopen
    retries = retries.increment(
  File "/home/airflow/.local/lib/python3.8/site-packages/urllib3/util/retry.py", line 525, in increment
    raise six.reraise(type(error), error, _stacktrace)
  File "/home/airflow/.local/lib/python3.8/site-packages/urllib3/packages/six.py", line 770, in reraise
    raise value
  File "/home/airflow/.local/lib/python3.8/site-packages/urllib3/connectionpool.py", line 715, in urlopen
    httplib_response = self._make_request(
  File "/home/airflow/.local/lib/python3.8/site-packages/urllib3/connectionpool.py", line 404, in _make_request
    self._validate_conn(conn)
  File "/home/airflow/.local/lib/python3.8/site-packages/urllib3/connectionpool.py", line 1058, in _validate_conn
    conn.connect()
  File "/home/airflow/.local/lib/python3.8/site-packages/urllib3/connection.py", line 363, in connect
    self.sock = conn = self._new_conn()
  File "/home/airflow/.local/lib/python3.8/site-packages/urllib3/connection.py", line 186, in _new_conn
    raise NewConnectionError(
urllib3.exceptions.NewConnectionError: <botocore.awsrequest.AWSHTTPSConnection object at 0xffff935e6a00>: Failed to establish a new connection: [Errno -2] Name or service not known

During handling of the above exception, another exception occurred:

Traceback (most recent call last):
  File "/home/airflow/.local/lib/python3.8/site-packages/airflow/models/taskinstance.py", line 444, in _execute_task
    result = _execute_callable(context=context, **execute_callable_kwargs)
  File "/home/airflow/.local/lib/python3.8/site-packages/airflow/models/taskinstance.py", line 414, in _execute_callable
    return execute_callable(context=context, **execute_callable_kwargs)
  File "/home/airflow/.local/lib/python3.8/site-packages/airflow/operators/python.py", line 200, in execute
    return_value = self.execute_callable()
  File "/home/airflow/.local/lib/python3.8/site-packages/airflow/operators/python.py", line 217, in execute_callable
    return self.python_callable(*self.op_args, **self.op_kwargs)
  File "/opt/airflow/dags/dag_download.py", line 66, in check_if_data_exists
    response = s3_client.list_objects_v2(Bucket=S3_BUCKET, Prefix=prefix)
  File "/home/airflow/.local/lib/python3.8/site-packages/botocore/client.py", line 553, in _api_call
    return self._make_api_call(operation_name, kwargs)
  File "/home/airflow/.local/lib/python3.8/site-packages/botocore/client.py", line 989, in _make_api_call
    http, parsed_response = self._make_request(
  File "/home/airflow/.local/lib/python3.8/site-packages/botocore/client.py", line 1015, in _make_request
    return self._endpoint.make_request(operation_model, request_dict)
  File "/home/airflow/.local/lib/python3.8/site-packages/botocore/endpoint.py", line 119, in make_request
    return self._send_request(request_dict, operation_model)
  File "/home/airflow/.local/lib/python3.8/site-packages/botocore/endpoint.py", line 202, in _send_request
    while self._needs_retry(
  File "/home/airflow/.local/lib/python3.8/site-packages/botocore/endpoint.py", line 354, in _needs_retry
    responses = self._event_emitter.emit(
  File "/home/airflow/.local/lib/python3.8/site-packages/botocore/hooks.py", line 412, in emit
    return self._emitter.emit(aliased_event_name, **kwargs)
  File "/home/airflow/.local/lib/python3.8/site-packages/botocore/hooks.py", line 256, in emit
    return self._emit(event_name, kwargs)
  File "/home/airflow/.local/lib/python3.8/site-packages/botocore/hooks.py", line 239, in _emit
    response = handler(**kwargs)
  File "/home/airflow/.local/lib/python3.8/site-packages/botocore/retryhandler.py", line 207, in __call__
    if self._checker(**checker_kwargs):
  File "/home/airflow/.local/lib/python3.8/site-packages/botocore/retryhandler.py", line 284, in __call__
    should_retry = self._should_retry(
  File "/home/airflow/.local/lib/python3.8/site-packages/botocore/retryhandler.py", line 320, in _should_retry
    return self._checker(attempt_number, response, caught_exception)
  File "/home/airflow/.local/lib/python3.8/site-packages/botocore/retryhandler.py", line 363, in __call__
    checker_response = checker(
  File "/home/airflow/.local/lib/python3.8/site-packages/botocore/retryhandler.py", line 247, in __call__
    return self._check_caught_exception(
  File "/home/airflow/.local/lib/python3.8/site-packages/botocore/retryhandler.py", line 416, in _check_caught_exception
    raise caught_exception
  File "/home/airflow/.local/lib/python3.8/site-packages/botocore/endpoint.py", line 281, in _do_get_response
    http_response = self._send(request)
  File "/home/airflow/.local/lib/python3.8/site-packages/botocore/endpoint.py", line 377, in _send
    return self.http_session.send(request)
  File "/home/airflow/.local/lib/python3.8/site-packages/botocore/httpsession.py", line 493, in send
    raise EndpointConnectionError(endpoint_url=request.url, error=e)
botocore.exceptions.EndpointConnectionError: Could not connect to the endpoint URL: "https://bdi-aircraft-rafaelbraga.s3.amazonaws.com/?list-type=2&prefix=readsb-hist%2F2024%2F03%2F01%2F&encoding-type=url"
[2024-03-13T19:53:22.299+0000] {taskinstance.py:1149} INFO - Marking task as FAILED. dag_id=download_readsb_hist, task_id=check_if_data_exists, execution_date=20240313T190752, start_date=20240313T195320, end_date=20240313T195322
[2024-03-13T19:53:22.311+0000] {standard_task_runner.py:107} ERROR - Failed to execute job 17 for task check_if_data_exists (Could not connect to the endpoint URL: "https://bdi-aircraft-rafaelbraga.s3.amazonaws.com/?list-type=2&prefix=readsb-hist%2F2024%2F03%2F01%2F&encoding-type=url"; 552)
[2024-03-13T19:53:22.351+0000] {local_task_job_runner.py:234} INFO - Task exited with return code 1
[2024-03-13T19:53:22.377+0000] {taskinstance.py:3309} INFO - 0 downstream tasks scheduled from follow-on schedule check
