[2024-03-22T16:06:00.620+0000] {taskinstance.py:1979} INFO - Dependencies all met for dep_context=non-requeueable deps ti=<TaskInstance: aircraft_data_processing.download_and_prepare_data manual__2024-03-22T16:05:59.023744+00:00 [queued]>
[2024-03-22T16:06:00.624+0000] {taskinstance.py:1979} INFO - Dependencies all met for dep_context=requeueable deps ti=<TaskInstance: aircraft_data_processing.download_and_prepare_data manual__2024-03-22T16:05:59.023744+00:00 [queued]>
[2024-03-22T16:06:00.624+0000] {taskinstance.py:2193} INFO - Starting attempt 1 of 2
[2024-03-22T16:06:00.631+0000] {taskinstance.py:2214} INFO - Executing <Task(PythonOperator): download_and_prepare_data> on 2024-03-22 16:05:59.023744+00:00
[2024-03-22T16:06:00.645+0000] {standard_task_runner.py:60} INFO - Started process 291 to run task
[2024-03-22T16:06:00.648+0000] {standard_task_runner.py:87} INFO - Running: ['***', 'tasks', 'run', 'aircraft_data_processing', 'download_and_prepare_data', 'manual__2024-03-22T16:05:59.023744+00:00', '--job-id', '83', '--raw', '--subdir', 'DAGS_FOLDER/dag_prep_2.py', '--cfg-path', '/tmp/tmp9rjjtd0e']
[2024-03-22T16:06:00.650+0000] {standard_task_runner.py:88} INFO - Job 83: Subtask download_and_prepare_data
[2024-03-22T16:06:00.692+0000] {task_command.py:423} INFO - Running <TaskInstance: aircraft_data_processing.download_and_prepare_data manual__2024-03-22T16:05:59.023744+00:00 [running]> on host 58dabeb1f433
[2024-03-22T16:06:00.729+0000] {taskinstance.py:2510} INFO - Exporting env vars: AIRFLOW_CTX_DAG_OWNER='***' AIRFLOW_CTX_DAG_ID='aircraft_data_processing' AIRFLOW_CTX_TASK_ID='download_and_prepare_data' AIRFLOW_CTX_EXECUTION_DATE='2024-03-22T16:05:59.023744+00:00' AIRFLOW_CTX_TRY_NUMBER='1' AIRFLOW_CTX_DAG_RUN_ID='manual__2024-03-22T16:05:59.023744+00:00'
[2024-03-22T16:06:00.887+0000] {dag_prep_2.py:85} INFO - Starting data download...
[2024-03-22T16:06:01.571+0000] {dag_prep_2.py:91} INFO - iterativas
[2024-03-22T16:06:10.786+0000] {local_task_job_runner.py:302} WARNING - State of this instance has been externally set to None. Terminating instance.
[2024-03-22T16:06:10.794+0000] {process_utils.py:131} INFO - Sending 15 to group 291. PIDs of all processes in the group: [291]
[2024-03-22T16:06:10.795+0000] {process_utils.py:86} INFO - Sending the signal 15 to group 291
[2024-03-22T16:06:10.795+0000] {taskinstance.py:2480} ERROR - Received SIGTERM. Terminating subprocesses.
[2024-03-22T16:06:10.805+0000] {taskinstance.py:2728} ERROR - Task failed with exception
Traceback (most recent call last):
  File "/home/airflow/.local/lib/python3.8/site-packages/airflow/models/taskinstance.py", line 444, in _execute_task
    result = _execute_callable(context=context, **execute_callable_kwargs)
  File "/home/airflow/.local/lib/python3.8/site-packages/airflow/models/taskinstance.py", line 414, in _execute_callable
    return execute_callable(context=context, **execute_callable_kwargs)
  File "/home/airflow/.local/lib/python3.8/site-packages/airflow/operators/python.py", line 200, in execute
    return_value = self.execute_callable()
  File "/home/airflow/.local/lib/python3.8/site-packages/airflow/operators/python.py", line 217, in execute_callable
    return self.python_callable(*self.op_args, **self.op_kwargs)
  File "/opt/airflow/dags/dag_prep_2.py", line 152, in task_download_and_prepare_data
    formatted_data = download_and_prepare_data()
  File "/opt/airflow/dags/dag_prep_2.py", line 96, in download_and_prepare_data
    file_content = gzipfile.read().decode('utf-8')
  File "/usr/local/lib/python3.8/gzip.py", line 292, in read
    return self._buffer.read(size)
  File "/usr/local/lib/python3.8/gzip.py", line 485, in read
    buf = self._fp.read(io.DEFAULT_BUFFER_SIZE)
  File "/usr/local/lib/python3.8/gzip.py", line 96, in read
    self.file.read(size-self._length+read)
  File "/home/airflow/.local/lib/python3.8/site-packages/botocore/response.py", line 99, in read
    chunk = self._raw_stream.read(amt)
  File "/home/airflow/.local/lib/python3.8/site-packages/urllib3/response.py", line 567, in read
    data = self._fp_read(amt) if not fp_closed else b""
  File "/home/airflow/.local/lib/python3.8/site-packages/urllib3/response.py", line 533, in _fp_read
    return self._fp.read(amt) if amt is not None else self._fp.read()
  File "/usr/local/lib/python3.8/http/client.py", line 459, in read
    n = self.readinto(b)
  File "/usr/local/lib/python3.8/http/client.py", line 503, in readinto
    n = self.fp.readinto(b)
  File "/usr/local/lib/python3.8/socket.py", line 669, in readinto
    return self._sock.recv_into(b)
  File "/usr/local/lib/python3.8/ssl.py", line 1274, in recv_into
    return self.read(nbytes, buffer)
  File "/usr/local/lib/python3.8/ssl.py", line 1132, in read
    return self._sslobj.read(len, buffer)
  File "/home/airflow/.local/lib/python3.8/site-packages/airflow/models/taskinstance.py", line 2482, in signal_handler
    raise AirflowException("Task received SIGTERM signal")
airflow.exceptions.AirflowException: Task received SIGTERM signal
[2024-03-22T16:06:10.813+0000] {taskinstance.py:1149} INFO - Marking task as FAILED. dag_id=aircraft_data_processing, task_id=download_and_prepare_data, execution_date=20240322T160559, start_date=20240322T160600, end_date=20240322T160610
[2024-03-22T16:06:10.823+0000] {standard_task_runner.py:107} ERROR - Failed to execute job 83 for task download_and_prepare_data ((psycopg2.errors.ForeignKeyViolation) insert or update on table "task_fail" violates foreign key constraint "task_fail_ti_fkey"
DETAIL:  Key (dag_id, task_id, run_id, map_index)=(aircraft_data_processing, download_and_prepare_data, manual__2024-03-22T16:05:59.023744+00:00, -1) is not present in table "task_instance".

[SQL: INSERT INTO task_fail (task_id, dag_id, run_id, map_index, start_date, end_date, duration) VALUES (%(task_id)s, %(dag_id)s, %(run_id)s, %(map_index)s, %(start_date)s, %(end_date)s, %(duration)s) RETURNING task_fail.id]
[parameters: {'task_id': 'download_and_prepare_data', 'dag_id': 'aircraft_data_processing', 'run_id': 'manual__2024-03-22T16:05:59.023744+00:00', 'map_index': -1, 'start_date': datetime.datetime(2024, 3, 22, 16, 6, 0, 620562, tzinfo=Timezone('UTC')), 'end_date': datetime.datetime(2024, 3, 22, 16, 6, 10, 813291, tzinfo=Timezone('UTC')), 'duration': 10}]
(Background on this error at: https://sqlalche.me/e/14/gkpj); 291)
[2024-03-22T16:06:10.890+0000] {process_utils.py:79} INFO - Process psutil.Process(pid=291, status='terminated', exitcode=1, started='16:05:59') (291) terminated with exit code 1
